✅ Grok API key loaded successfully (length: 84 chars)
❌ Failed to initialize Grok: HTTPSConnectionPool(host='api.x.ai', port=443): Max retries exceeded with url: /v1/chat/completions (Caused by NameResolutionError("<urllib3.connection.HTTPSConnection object at 0x7f7fc42b1670>: Failed to resolve 'api.x.ai' ([Errno -3] Temporary failure in name resolution)"))
Traceback (most recent call last):
  File "/home/shahar42/Suumerizing_C_holy_grale_book/venv/lib/python3.12/site-packages/urllib3/connection.py", line 198, in _new_conn
    sock = connection.create_connection(
           ^^^^^^^^^^^^^^^^^^^^^^^^^^^^^
  File "/home/shahar42/Suumerizing_C_holy_grale_book/venv/lib/python3.12/site-packages/urllib3/util/connection.py", line 60, in create_connection
    for res in socket.getaddrinfo(host, port, family, socket.SOCK_STREAM):
               ^^^^^^^^^^^^^^^^^^^^^^^^^^^^^^^^^^^^^^^^^^^^^^^^^^^^^^^^^^
  File "/usr/lib/python3.12/socket.py", line 963, in getaddrinfo
    for res in _socket.getaddrinfo(host, port, family, type, proto, flags):
               ^^^^^^^^^^^^^^^^^^^^^^^^^^^^^^^^^^^^^^^^^^^^^^^^^^^^^^^^^^^
socket.gaierror: [Errno -3] Temporary failure in name resolution

The above exception was the direct cause of the following exception:

Traceback (most recent call last):
  File "/home/shahar42/Suumerizing_C_holy_grale_book/venv/lib/python3.12/site-packages/urllib3/connectionpool.py", line 787, in urlopen
    response = self._make_request(
               ^^^^^^^^^^^^^^^^^^^
  File "/home/shahar42/Suumerizing_C_holy_grale_book/venv/lib/python3.12/site-packages/urllib3/connectionpool.py", line 488, in _make_request
    raise new_e
  File "/home/shahar42/Suumerizing_C_holy_grale_book/venv/lib/python3.12/site-packages/urllib3/connectionpool.py", line 464, in _make_request
    self._validate_conn(conn)
  File "/home/shahar42/Suumerizing_C_holy_grale_book/venv/lib/python3.12/site-packages/urllib3/connectionpool.py", line 1093, in _validate_conn
    conn.connect()
  File "/home/shahar42/Suumerizing_C_holy_grale_book/venv/lib/python3.12/site-packages/urllib3/connection.py", line 753, in connect
    self.sock = sock = self._new_conn()
                       ^^^^^^^^^^^^^^^^
  File "/home/shahar42/Suumerizing_C_holy_grale_book/venv/lib/python3.12/site-packages/urllib3/connection.py", line 205, in _new_conn
    raise NameResolutionError(self.host, self, e) from e
urllib3.exceptions.NameResolutionError: <urllib3.connection.HTTPSConnection object at 0x7f7fc42b1670>: Failed to resolve 'api.x.ai' ([Errno -3] Temporary failure in name resolution)

The above exception was the direct cause of the following exception:

Traceback (most recent call last):
  File "/home/shahar42/Suumerizing_C_holy_grale_book/venv/lib/python3.12/site-packages/requests/adapters.py", line 486, in send
    resp = conn.urlopen(
           ^^^^^^^^^^^^^
  File "/home/shahar42/Suumerizing_C_holy_grale_book/venv/lib/python3.12/site-packages/urllib3/connectionpool.py", line 841, in urlopen
    retries = retries.increment(
              ^^^^^^^^^^^^^^^^^^
  File "/home/shahar42/Suumerizing_C_holy_grale_book/venv/lib/python3.12/site-packages/urllib3/util/retry.py", line 519, in increment
    raise MaxRetryError(_pool, url, reason) from reason  # type: ignore[arg-type]
    ^^^^^^^^^^^^^^^^^^^^^^^^^^^^^^^^^^^^^^^^^^^^^^^^^^^
urllib3.exceptions.MaxRetryError: HTTPSConnectionPool(host='api.x.ai', port=443): Max retries exceeded with url: /v1/chat/completions (Caused by NameResolutionError("<urllib3.connection.HTTPSConnection object at 0x7f7fc42b1670>: Failed to resolve 'api.x.ai' ([Errno -3] Temporary failure in name resolution)"))

During handling of the above exception, another exception occurred:

Traceback (most recent call last):
  File "/home/shahar42/Suumerizing_C_holy_grale_book/books/extract_os_three_pieces.py", line 258, in <module>
    main()
  File "/home/shahar42/Suumerizing_C_holy_grale_book/books/extract_os_three_pieces.py", line 246, in main
    engine = OSExtractionEngine(pdf_path, output_dir)
             ^^^^^^^^^^^^^^^^^^^^^^^^^^^^^^^^^^^^^^^^
  File "/home/shahar42/Suumerizing_C_holy_grale_book/books/extract_os_three_pieces.py", line 51, in __init__
    self.processor = GrokAtomicProcessor(api_key)
                     ^^^^^^^^^^^^^^^^^^^^^^^^^^^^
  File "/home/shahar42/Suumerizing_C_holy_grale_book/processors/grok_processor.py", line 28, in __init__
    self._test_connection()
  File "/home/shahar42/Suumerizing_C_holy_grale_book/processors/grok_processor.py", line 50, in _test_connection
    response = requests.post(
               ^^^^^^^^^^^^^^
  File "/home/shahar42/Suumerizing_C_holy_grale_book/venv/lib/python3.12/site-packages/requests/api.py", line 115, in post
    return request("post", url, data=data, json=json, **kwargs)
           ^^^^^^^^^^^^^^^^^^^^^^^^^^^^^^^^^^^^^^^^^^^^^^^^^^^^
  File "/home/shahar42/Suumerizing_C_holy_grale_book/venv/lib/python3.12/site-packages/requests/api.py", line 59, in request
    return session.request(method=method, url=url, **kwargs)
           ^^^^^^^^^^^^^^^^^^^^^^^^^^^^^^^^^^^^^^^^^^^^^^^^^
  File "/home/shahar42/Suumerizing_C_holy_grale_book/venv/lib/python3.12/site-packages/requests/sessions.py", line 589, in request
    resp = self.send(prep, **send_kwargs)
           ^^^^^^^^^^^^^^^^^^^^^^^^^^^^^^
  File "/home/shahar42/Suumerizing_C_holy_grale_book/venv/lib/python3.12/site-packages/requests/sessions.py", line 703, in send
    r = adapter.send(request, **kwargs)
        ^^^^^^^^^^^^^^^^^^^^^^^^^^^^^^^
  File "/home/shahar42/Suumerizing_C_holy_grale_book/venv/lib/python3.12/site-packages/requests/adapters.py", line 519, in send
    raise ConnectionError(e, request=request)
requests.exceptions.ConnectionError: HTTPSConnectionPool(host='api.x.ai', port=443): Max retries exceeded with url: /v1/chat/completions (Caused by NameResolutionError("<urllib3.connection.HTTPSConnection object at 0x7f7fc42b1670>: Failed to resolve 'api.x.ai' ([Errno -3] Temporary failure in name resolution)"))
